{
 "cells": [
  {
   "cell_type": "code",
   "execution_count": 1,
   "metadata": {},
   "outputs": [
    {
     "ename": "ModuleNotFoundError",
     "evalue": "No module named 'cv2'",
     "output_type": "error",
     "traceback": [
      "\u001b[1;31m---------------------------------------------------------------------------\u001b[0m",
      "\u001b[1;31mModuleNotFoundError\u001b[0m                       Traceback (most recent call last)",
      "\u001b[1;32m<ipython-input-1-39301cda310a>\u001b[0m in \u001b[0;36m<module>\u001b[1;34m()\u001b[0m\n\u001b[1;32m----> 1\u001b[1;33m \u001b[1;32mimport\u001b[0m \u001b[0mcv2\u001b[0m\u001b[1;33m\u001b[0m\u001b[0m\n\u001b[0m\u001b[0;32m      2\u001b[0m \u001b[1;32mimport\u001b[0m \u001b[0mnumpy\u001b[0m \u001b[1;32mas\u001b[0m \u001b[0mnp\u001b[0m\u001b[1;33m\u001b[0m\u001b[0m\n\u001b[0;32m      3\u001b[0m \u001b[1;32mimport\u001b[0m \u001b[0msys\u001b[0m\u001b[1;33m\u001b[0m\u001b[0m\n\u001b[0;32m      4\u001b[0m \u001b[1;32mimport\u001b[0m \u001b[0mtime\u001b[0m\u001b[1;33m\u001b[0m\u001b[0m\n\u001b[0;32m      5\u001b[0m \u001b[1;32mif\u001b[0m \u001b[0mlen\u001b[0m\u001b[1;33m(\u001b[0m\u001b[0msys\u001b[0m\u001b[1;33m.\u001b[0m\u001b[0margv\u001b[0m\u001b[1;33m)\u001b[0m\u001b[1;33m>\u001b[0m\u001b[1;36m1\u001b[0m\u001b[1;33m:\u001b[0m\u001b[1;33m\u001b[0m\u001b[0m\n",
      "\u001b[1;31mModuleNotFoundError\u001b[0m: No module named 'cv2'"
     ]
    }
   ],
   "source": [
    "import cv2\n",
    "import numpy as np\n",
    "import sys\n",
    "import time\n",
    "if len(sys.argv)>1:\n",
    "    inputImage = cv2.imread(sys.argv[1])\n",
    "else:\n",
    "    inputImage = cv2.imread(\"qrcode-learnopencv.jpg\")\n",
    "# Display barcode and QR code location\n",
    "def display(im, bbox):\n",
    "    n = len(bbox)\n",
    "    for j in range(n):\n",
    "        cv2.line(im, tuple(bbox[j][0]), tuple(bbox[ (j+1) % n][0]), (255,0,0), 3)\n",
    " \n",
    "    # Display results\n",
    "    cv2.imshow(\"Results\", im)    "
   ]
  },
  {
   "cell_type": "code",
   "execution_count": 2,
   "metadata": {},
   "outputs": [
    {
     "name": "stdout",
     "output_type": "stream",
     "text": [
      "Collecting opencv-python\n"
     ]
    },
    {
     "name": "stderr",
     "output_type": "stream",
     "text": [
      "  Retrying (Retry(total=4, connect=None, read=None, redirect=None, status=None)) after connection broken by 'NewConnectionError('<pip._vendor.urllib3.connection.VerifiedHTTPSConnection object at 0x000001F626F53F60>: Failed to establish a new connection: [Errno 11001] getaddrinfo failed',)': /packages/9c/88/06cdc6239013e13aec97f474638fc4e7c00e5b7fb954a1d0ec2a5fc8db7a/opencv_python-4.1.1.26-cp36-cp36m-win_amd64.whl\n",
      "  Retrying (Retry(total=3, connect=None, read=None, redirect=None, status=None)) after connection broken by 'NewConnectionError('<pip._vendor.urllib3.connection.VerifiedHTTPSConnection object at 0x000001F626F5A6A0>: Failed to establish a new connection: [Errno 11001] getaddrinfo failed',)': /packages/9c/88/06cdc6239013e13aec97f474638fc4e7c00e5b7fb954a1d0ec2a5fc8db7a/opencv_python-4.1.1.26-cp36-cp36m-win_amd64.whl\n",
      "  Retrying (Retry(total=2, connect=None, read=None, redirect=None, status=None)) after connection broken by 'NewConnectionError('<pip._vendor.urllib3.connection.VerifiedHTTPSConnection object at 0x000001F626F5A438>: Failed to establish a new connection: [Errno 11001] getaddrinfo failed',)': /packages/9c/88/06cdc6239013e13aec97f474638fc4e7c00e5b7fb954a1d0ec2a5fc8db7a/opencv_python-4.1.1.26-cp36-cp36m-win_amd64.whl\n",
      "  Retrying (Retry(total=1, connect=None, read=None, redirect=None, status=None)) after connection broken by 'NewConnectionError('<pip._vendor.urllib3.connection.VerifiedHTTPSConnection object at 0x000001F626F5AE80>: Failed to establish a new connection: [Errno 11001] getaddrinfo failed',)': /packages/9c/88/06cdc6239013e13aec97f474638fc4e7c00e5b7fb954a1d0ec2a5fc8db7a/opencv_python-4.1.1.26-cp36-cp36m-win_amd64.whl\n",
      "  Retrying (Retry(total=0, connect=None, read=None, redirect=None, status=None)) after connection broken by 'NewConnectionError('<pip._vendor.urllib3.connection.VerifiedHTTPSConnection object at 0x000001F626F5A978>: Failed to establish a new connection: [Errno 11001] getaddrinfo failed',)': /packages/9c/88/06cdc6239013e13aec97f474638fc4e7c00e5b7fb954a1d0ec2a5fc8db7a/opencv_python-4.1.1.26-cp36-cp36m-win_amd64.whl\n",
      "Could not install packages due to an EnvironmentError: HTTPSConnectionPool(host='files.pythonhosted.org', port=443): Max retries exceeded with url: /packages/9c/88/06cdc6239013e13aec97f474638fc4e7c00e5b7fb954a1d0ec2a5fc8db7a/opencv_python-4.1.1.26-cp36-cp36m-win_amd64.whl (Caused by ReadTimeoutError(\"HTTPSConnectionPool(host='files.pythonhosted.org', port=443): Read timed out. (read timeout=15)\",))\n",
      "\n",
      "You are using pip version 10.0.1, however version 19.3.1 is available.\n",
      "You should consider upgrading via the 'python -m pip install --upgrade pip' command.\n"
     ]
    }
   ],
   "source": [
    "!pip install opencv-python"
   ]
  },
  {
   "cell_type": "code",
   "execution_count": null,
   "metadata": {},
   "outputs": [],
   "source": []
  },
  {
   "cell_type": "code",
   "execution_count": null,
   "metadata": {},
   "outputs": [],
   "source": []
  }
 ],
 "metadata": {
  "kernelspec": {
   "display_name": "Python 3",
   "language": "python",
   "name": "python3"
  },
  "language_info": {
   "codemirror_mode": {
    "name": "ipython",
    "version": 3
   },
   "file_extension": ".py",
   "mimetype": "text/x-python",
   "name": "python",
   "nbconvert_exporter": "python",
   "pygments_lexer": "ipython3",
   "version": "3.6.5"
  }
 },
 "nbformat": 4,
 "nbformat_minor": 2
}
